[2024-06-25T00:46:42.191+0000] {local_task_job_runner.py:120} INFO - ::group::Pre task execution logs
[2024-06-25T00:46:42.208+0000] {taskinstance.py:2076} INFO - Dependencies all met for dep_context=non-requeueable deps ti=<TaskInstance: create_table_6.upload_file_to_yandex_s3 scheduled__2024-06-24T12:00:00+00:00 [queued]>
[2024-06-25T00:46:42.215+0000] {taskinstance.py:2076} INFO - Dependencies all met for dep_context=requeueable deps ti=<TaskInstance: create_table_6.upload_file_to_yandex_s3 scheduled__2024-06-24T12:00:00+00:00 [queued]>
[2024-06-25T00:46:42.215+0000] {taskinstance.py:2306} INFO - Starting attempt 1 of 2
[2024-06-25T00:46:42.228+0000] {taskinstance.py:2330} INFO - Executing <Task(PythonOperator): upload_file_to_yandex_s3> on 2024-06-24 12:00:00+00:00
[2024-06-25T00:46:42.233+0000] {warnings.py:110} WARNING - /home/airflow/.local/lib/python3.12/site-packages/airflow/task/task_runner/standard_task_runner.py:61: DeprecationWarning: This process (pid=70) is multi-threaded, use of fork() may lead to deadlocks in the child.
  pid = os.fork()

[2024-06-25T00:46:42.234+0000] {standard_task_runner.py:63} INFO - Started process 71 to run task
[2024-06-25T00:46:42.235+0000] {standard_task_runner.py:90} INFO - Running: ['airflow', 'tasks', 'run', 'create_table_6', 'upload_file_to_yandex_s3', 'scheduled__2024-06-24T12:00:00+00:00', '--job-id', '59', '--raw', '--subdir', 'DAGS_FOLDER/etl.py', '--cfg-path', '/tmp/tmpvkjuv_te']
[2024-06-25T00:46:42.237+0000] {standard_task_runner.py:91} INFO - Job 59: Subtask upload_file_to_yandex_s3
[2024-06-25T00:46:42.274+0000] {task_command.py:426} INFO - Running <TaskInstance: create_table_6.upload_file_to_yandex_s3 scheduled__2024-06-24T12:00:00+00:00 [running]> on host 5ba0933a4dfa
[2024-06-25T00:46:42.341+0000] {taskinstance.py:2648} INFO - Exporting env vars: AIRFLOW_CTX_DAG_OWNER='airflow' AIRFLOW_CTX_DAG_ID='create_table_6' AIRFLOW_CTX_TASK_ID='upload_file_to_yandex_s3' AIRFLOW_CTX_EXECUTION_DATE='2024-06-24T12:00:00+00:00' AIRFLOW_CTX_TRY_NUMBER='1' AIRFLOW_CTX_DAG_RUN_ID='scheduled__2024-06-24T12:00:00+00:00'
[2024-06-25T00:46:42.342+0000] {taskinstance.py:430} INFO - ::endgroup::
[2024-06-25T00:46:42.366+0000] {taskinstance.py:441} INFO - ::group::Post task execution logs
[2024-06-25T00:46:42.373+0000] {taskinstance.py:2905} ERROR - Task failed with exception
Traceback (most recent call last):
  File "/home/airflow/.local/lib/python3.12/site-packages/airflow/models/taskinstance.py", line 465, in _execute_task
    result = _execute_callable(context=context, **execute_callable_kwargs)
             ^^^^^^^^^^^^^^^^^^^^^^^^^^^^^^^^^^^^^^^^^^^^^^^^^^^^^^^^^^^^^
  File "/home/airflow/.local/lib/python3.12/site-packages/airflow/models/taskinstance.py", line 432, in _execute_callable
    return execute_callable(context=context, **execute_callable_kwargs)
           ^^^^^^^^^^^^^^^^^^^^^^^^^^^^^^^^^^^^^^^^^^^^^^^^^^^^^^^^^^^^
  File "/home/airflow/.local/lib/python3.12/site-packages/airflow/models/baseoperator.py", line 400, in wrapper
    return func(self, *args, **kwargs)
           ^^^^^^^^^^^^^^^^^^^^^^^^^^^
  File "/home/airflow/.local/lib/python3.12/site-packages/airflow/operators/python.py", line 235, in execute
    return_value = self.execute_callable()
                   ^^^^^^^^^^^^^^^^^^^^^^^
  File "/home/airflow/.local/lib/python3.12/site-packages/airflow/operators/python.py", line 252, in execute_callable
    return self.python_callable(*self.op_args, **self.op_kwargs)
           ^^^^^^^^^^^^^^^^^^^^^^^^^^^^^^^^^^^^^^^^^^^^^^^^^^^^^
  File "/opt/airflow/dags/etl.py", line 41, in upload_file_to_yandex_s3
    hook = YandexCloudBaseHook(yandex_conn_id="yandex_cloud_default")
           ^^^^^^^^^^^^^^^^^^^^^^^^^^^^^^^^^^^^^^^^^^^^^^^^^^^^^^^^^^
  File "/home/airflow/.local/lib/python3.12/site-packages/airflow/providers/yandex/hooks/yandex.py", line 133, in __init__
    self.connection = self.get_connection(self.connection_id)
                      ^^^^^^^^^^^^^^^^^^^^^^^^^^^^^^^^^^^^^^^
  File "/home/airflow/.local/lib/python3.12/site-packages/airflow/hooks/base.py", line 83, in get_connection
    conn = Connection.get_connection_from_secrets(conn_id)
           ^^^^^^^^^^^^^^^^^^^^^^^^^^^^^^^^^^^^^^^^^^^^^^^
  File "/home/airflow/.local/lib/python3.12/site-packages/airflow/models/connection.py", line 519, in get_connection_from_secrets
    raise AirflowNotFoundException(f"The conn_id `{conn_id}` isn't defined")
airflow.exceptions.AirflowNotFoundException: The conn_id `yandex_cloud_default` isn't defined
[2024-06-25T00:46:42.384+0000] {taskinstance.py:1206} INFO - Marking task as UP_FOR_RETRY. dag_id=create_table_6, task_id=upload_file_to_yandex_s3, run_id=scheduled__2024-06-24T12:00:00+00:00, execution_date=20240624T120000, start_date=20240625T004642, end_date=20240625T004642
[2024-06-25T00:46:42.395+0000] {standard_task_runner.py:110} ERROR - Failed to execute job 59 for task upload_file_to_yandex_s3 (The conn_id `yandex_cloud_default` isn't defined; 71)
[2024-06-25T00:46:42.408+0000] {local_task_job_runner.py:240} INFO - Task exited with return code 1
[2024-06-25T00:46:42.419+0000] {taskinstance.py:3498} INFO - 0 downstream tasks scheduled from follow-on schedule check
[2024-06-25T00:46:42.422+0000] {local_task_job_runner.py:222} INFO - ::endgroup::
