[2024-06-25T22:13:37.442+0000] {local_task_job_runner.py:120} INFO - ::group::Pre task execution logs
[2024-06-25T22:13:37.456+0000] {taskinstance.py:2076} INFO - Dependencies all met for dep_context=non-requeueable deps ti=<TaskInstance: create_movie_dataset_v1.get_movies scheduled__2024-06-25T00:00:00+00:00 [queued]>
[2024-06-25T22:13:37.462+0000] {taskinstance.py:2076} INFO - Dependencies all met for dep_context=requeueable deps ti=<TaskInstance: create_movie_dataset_v1.get_movies scheduled__2024-06-25T00:00:00+00:00 [queued]>
[2024-06-25T22:13:37.462+0000] {taskinstance.py:2306} INFO - Starting attempt 2 of 3
[2024-06-25T22:13:37.472+0000] {taskinstance.py:2330} INFO - Executing <Task(PythonOperator): get_movies> on 2024-06-25 00:00:00+00:00
[2024-06-25T22:13:37.475+0000] {warnings.py:110} WARNING - /home/airflow/.local/lib/python3.12/site-packages/airflow/task/task_runner/standard_task_runner.py:61: DeprecationWarning: This process (pid=781) is multi-threaded, use of fork() may lead to deadlocks in the child.
  pid = os.fork()

[2024-06-25T22:13:37.476+0000] {standard_task_runner.py:90} INFO - Running: ['airflow', 'tasks', 'run', 'create_movie_dataset_v1', 'get_movies', 'scheduled__2024-06-25T00:00:00+00:00', '--job-id', '69', '--raw', '--subdir', 'DAGS_FOLDER/etl.py', '--cfg-path', '/tmp/tmps3__q906']
[2024-06-25T22:13:37.477+0000] {standard_task_runner.py:63} INFO - Started process 782 to run task
[2024-06-25T22:13:37.477+0000] {standard_task_runner.py:91} INFO - Job 69: Subtask get_movies
[2024-06-25T22:13:37.508+0000] {task_command.py:426} INFO - Running <TaskInstance: create_movie_dataset_v1.get_movies scheduled__2024-06-25T00:00:00+00:00 [running]> on host ad6ccfebc5a6
[2024-06-25T22:13:37.558+0000] {taskinstance.py:2648} INFO - Exporting env vars: AIRFLOW_CTX_DAG_OWNER='airflow' AIRFLOW_CTX_DAG_ID='create_movie_dataset_v1' AIRFLOW_CTX_TASK_ID='get_movies' AIRFLOW_CTX_EXECUTION_DATE='2024-06-25T00:00:00+00:00' AIRFLOW_CTX_TRY_NUMBER='2' AIRFLOW_CTX_DAG_RUN_ID='scheduled__2024-06-25T00:00:00+00:00'
[2024-06-25T22:13:37.558+0000] {taskinstance.py:430} INFO - ::endgroup::
[2024-06-25T22:13:39.967+0000] {taskinstance.py:441} INFO - ::group::Post task execution logs
[2024-06-25T22:13:39.969+0000] {taskinstance.py:2905} ERROR - Task failed with exception
Traceback (most recent call last):
  File "/home/airflow/.local/lib/python3.12/site-packages/airflow/models/taskinstance.py", line 465, in _execute_task
    result = _execute_callable(context=context, **execute_callable_kwargs)
             ^^^^^^^^^^^^^^^^^^^^^^^^^^^^^^^^^^^^^^^^^^^^^^^^^^^^^^^^^^^^^
  File "/home/airflow/.local/lib/python3.12/site-packages/airflow/models/taskinstance.py", line 432, in _execute_callable
    return execute_callable(context=context, **execute_callable_kwargs)
           ^^^^^^^^^^^^^^^^^^^^^^^^^^^^^^^^^^^^^^^^^^^^^^^^^^^^^^^^^^^^
  File "/home/airflow/.local/lib/python3.12/site-packages/airflow/models/baseoperator.py", line 400, in wrapper
    return func(self, *args, **kwargs)
           ^^^^^^^^^^^^^^^^^^^^^^^^^^^
  File "/home/airflow/.local/lib/python3.12/site-packages/airflow/operators/python.py", line 235, in execute
    return_value = self.execute_callable()
                   ^^^^^^^^^^^^^^^^^^^^^^^
  File "/home/airflow/.local/lib/python3.12/site-packages/airflow/operators/python.py", line 252, in execute_callable
    return self.python_callable(*self.op_args, **self.op_kwargs)
           ^^^^^^^^^^^^^^^^^^^^^^^^^^^^^^^^^^^^^^^^^^^^^^^^^^^^^
  File "/opt/airflow/dags/tasks/get_movies.py", line 16, in get_movies
    with open("data/movie_data.json", "w", encoding="utf-8") as file:
         ^^^^^^^^^^^^^^^^^^^^^^^^^^^^^^^^^^^^^^^^^^^^^^^^^^^
FileNotFoundError: [Errno 2] No such file or directory: 'data/movie_data.json'
[2024-06-25T22:13:39.977+0000] {taskinstance.py:1206} INFO - Marking task as UP_FOR_RETRY. dag_id=create_movie_dataset_v1, task_id=get_movies, run_id=scheduled__2024-06-25T00:00:00+00:00, execution_date=20240625T000000, start_date=20240625T221337, end_date=20240625T221339
[2024-06-25T22:13:39.987+0000] {standard_task_runner.py:110} ERROR - Failed to execute job 69 for task get_movies ([Errno 2] No such file or directory: 'data/movie_data.json'; 782)
[2024-06-25T22:13:40.016+0000] {local_task_job_runner.py:240} INFO - Task exited with return code 1
[2024-06-25T22:13:40.027+0000] {taskinstance.py:3498} INFO - 0 downstream tasks scheduled from follow-on schedule check
[2024-06-25T22:13:40.029+0000] {local_task_job_runner.py:222} INFO - ::endgroup::
