[2024-07-01T01:15:52.657+0000] {local_task_job_runner.py:120} INFO - ::group::Pre task execution logs
[2024-07-01T01:15:52.674+0000] {taskinstance.py:2076} INFO - Dependencies all met for dep_context=non-requeueable deps ti=<TaskInstance: model_training_v15.train_model scheduled__2024-06-30T00:00:00+00:00 [queued]>
[2024-07-01T01:15:52.680+0000] {taskinstance.py:2076} INFO - Dependencies all met for dep_context=requeueable deps ti=<TaskInstance: model_training_v15.train_model scheduled__2024-06-30T00:00:00+00:00 [queued]>
[2024-07-01T01:15:52.680+0000] {taskinstance.py:2306} INFO - Starting attempt 1 of 2
[2024-07-01T01:15:52.689+0000] {taskinstance.py:2330} INFO - Executing <Task(PythonOperator): train_model> on 2024-06-30 00:00:00+00:00
[2024-07-01T01:15:52.696+0000] {warnings.py:110} WARNING - /home/airflow/.local/lib/python3.12/site-packages/airflow/task/task_runner/standard_task_runner.py:61: DeprecationWarning: This process (pid=172) is multi-threaded, use of fork() may lead to deadlocks in the child.
  pid = os.fork()

[2024-07-01T01:15:52.700+0000] {standard_task_runner.py:63} INFO - Started process 194 to run task
[2024-07-01T01:15:52.696+0000] {standard_task_runner.py:90} INFO - Running: ['airflow', 'tasks', 'run', 'model_training_v15', 'train_model', 'scheduled__2024-06-30T00:00:00+00:00', '--job-id', '719', '--raw', '--subdir', 'DAGS_FOLDER/model_training.py', '--cfg-path', '/tmp/tmprsi6a6mt']
[2024-07-01T01:15:52.701+0000] {standard_task_runner.py:91} INFO - Job 719: Subtask train_model
[2024-07-01T01:15:52.740+0000] {task_command.py:426} INFO - Running <TaskInstance: model_training_v15.train_model scheduled__2024-06-30T00:00:00+00:00 [running]> on host c5db54028fc7
[2024-07-01T01:15:52.815+0000] {taskinstance.py:2648} INFO - Exporting env vars: AIRFLOW_CTX_DAG_OWNER='airflow' AIRFLOW_CTX_DAG_ID='model_training_v15' AIRFLOW_CTX_TASK_ID='train_model' AIRFLOW_CTX_EXECUTION_DATE='2024-06-30T00:00:00+00:00' AIRFLOW_CTX_TRY_NUMBER='1' AIRFLOW_CTX_DAG_RUN_ID='scheduled__2024-06-30T00:00:00+00:00'
[2024-07-01T01:15:52.816+0000] {taskinstance.py:430} INFO - ::endgroup::
[2024-07-01T01:15:52.863+0000] {logging_mixin.py:188} WARNING - 2024/07/01 01:15:52 WARNING mlflow.utils.git_utils: Failed to import Git (the Git executable is probably not on your PATH), so Git SHA is not available. Error: Failed to initialize: Bad git executable.
The git executable must be specified in one of the following ways:
    - be included in your $PATH
    - be set via $GIT_PYTHON_GIT_EXECUTABLE
    - explicitly set via git.refresh(<full-path-to-git-executable>)

All git commands will error until this is rectified.

This initial message can be silenced or aggravated in the future by setting the
$GIT_PYTHON_REFRESH environment variable. Use one of the following values:
    - quiet|q|silence|s|silent|none|n|0: for no message or exception
    - warn|w|warning|log|l|1: for a warning message (logging level CRITICAL, displayed by default)
    - error|e|exception|raise|r|2: for a raised exception

Example:
    export GIT_PYTHON_REFRESH=quiet
[2024-07-01T01:15:52.889+0000] {taskinstance.py:441} INFO - ::group::Post task execution logs
[2024-07-01T01:15:52.889+0000] {taskinstance.py:2905} ERROR - Task failed with exception
Traceback (most recent call last):
  File "/home/airflow/.local/lib/python3.12/site-packages/airflow/models/taskinstance.py", line 465, in _execute_task
    result = _execute_callable(context=context, **execute_callable_kwargs)
             ^^^^^^^^^^^^^^^^^^^^^^^^^^^^^^^^^^^^^^^^^^^^^^^^^^^^^^^^^^^^^
  File "/home/airflow/.local/lib/python3.12/site-packages/airflow/models/taskinstance.py", line 432, in _execute_callable
    return execute_callable(context=context, **execute_callable_kwargs)
           ^^^^^^^^^^^^^^^^^^^^^^^^^^^^^^^^^^^^^^^^^^^^^^^^^^^^^^^^^^^^
  File "/home/airflow/.local/lib/python3.12/site-packages/airflow/models/baseoperator.py", line 400, in wrapper
    return func(self, *args, **kwargs)
           ^^^^^^^^^^^^^^^^^^^^^^^^^^^
  File "/home/airflow/.local/lib/python3.12/site-packages/airflow/operators/python.py", line 235, in execute
    return_value = self.execute_callable()
                   ^^^^^^^^^^^^^^^^^^^^^^^
  File "/home/airflow/.local/lib/python3.12/site-packages/airflow/operators/python.py", line 252, in execute_callable
    return self.python_callable(*self.op_args, **self.op_kwargs)
           ^^^^^^^^^^^^^^^^^^^^^^^^^^^^^^^^^^^^^^^^^^^^^^^^^^^^^
  File "/opt/airflow/dags/model_training.py", line 61, in main
    mlflow.sklearn.save_model(model, "iris_model")
  File "/home/airflow/.local/lib/python3.12/site-packages/mlflow/sklearn/__init__.py", line 244, in save_model
    _validate_and_prepare_target_save_path(path)
  File "/home/airflow/.local/lib/python3.12/site-packages/mlflow/utils/model_utils.py", line 267, in _validate_and_prepare_target_save_path
    raise MlflowException(
mlflow.exceptions.MlflowException: Path 'iris_model' already exists and is not empty
[2024-07-01T01:15:52.900+0000] {taskinstance.py:1206} INFO - Marking task as UP_FOR_RETRY. dag_id=model_training_v15, task_id=train_model, run_id=scheduled__2024-06-30T00:00:00+00:00, execution_date=20240630T000000, start_date=20240701T011552, end_date=20240701T011552
[2024-07-01T01:15:52.909+0000] {standard_task_runner.py:110} ERROR - Failed to execute job 719 for task train_model (Path 'iris_model' already exists and is not empty; 194)
[2024-07-01T01:15:52.954+0000] {local_task_job_runner.py:240} INFO - Task exited with return code 1
[2024-07-01T01:15:52.964+0000] {taskinstance.py:3498} INFO - 0 downstream tasks scheduled from follow-on schedule check
[2024-07-01T01:15:52.967+0000] {local_task_job_runner.py:222} INFO - ::endgroup::
