[2024-07-06T22:09:02.429+0000] {task_context_logger.py:104} WARNING - Marking task instance <TaskInstance: model_training_v50.create_bucket scheduled__2024-07-05T00:00:00+00:00 [queued]> stuck in queued as failed. If the task instance has available retries, it will be retried.
[2024-07-06T22:09:02.517+0000] {task_context_logger.py:104} ERROR - Executor reports task instance <TaskInstance: model_training_v50.create_bucket scheduled__2024-07-05T00:00:00+00:00 [queued]> finished (failed) although the task says it's queued. (Info: None) Was the task killed externally?
