[2024-06-26T01:24:15.071+0000] {local_task_job_runner.py:120} INFO - ::group::Pre task execution logs
[2024-06-26T01:24:15.175+0000] {taskinstance.py:2076} INFO - Dependencies all met for dep_context=non-requeueable deps ti=<TaskInstance: create_movie_dataset_v7.insert_data_to_db scheduled__2024-06-25T12:00:00+00:00 [queued]>
[2024-06-26T01:24:15.181+0000] {taskinstance.py:2076} INFO - Dependencies all met for dep_context=requeueable deps ti=<TaskInstance: create_movie_dataset_v7.insert_data_to_db scheduled__2024-06-25T12:00:00+00:00 [queued]>
[2024-06-26T01:24:15.181+0000] {taskinstance.py:2306} INFO - Starting attempt 1 of 2
[2024-06-26T01:24:15.190+0000] {taskinstance.py:2330} INFO - Executing <Task(PythonOperator): insert_data_to_db> on 2024-06-25 12:00:00+00:00
[2024-06-26T01:24:15.195+0000] {warnings.py:110} WARNING - /home/airflow/.local/lib/python3.12/site-packages/airflow/task/task_runner/standard_task_runner.py:61: DeprecationWarning: This process (pid=2787) is multi-threaded, use of fork() may lead to deadlocks in the child.
  pid = os.fork()

[2024-06-26T01:24:15.196+0000] {standard_task_runner.py:63} INFO - Started process 2789 to run task
[2024-06-26T01:24:15.196+0000] {standard_task_runner.py:90} INFO - Running: ['airflow', 'tasks', 'run', 'create_movie_dataset_v7', 'insert_data_to_db', 'scheduled__2024-06-25T12:00:00+00:00', '--job-id', '86', '--raw', '--subdir', 'DAGS_FOLDER/etl.py', '--cfg-path', '/tmp/tmp4_vn81pv']
[2024-06-26T01:24:15.198+0000] {standard_task_runner.py:91} INFO - Job 86: Subtask insert_data_to_db
[2024-06-26T01:24:15.231+0000] {task_command.py:426} INFO - Running <TaskInstance: create_movie_dataset_v7.insert_data_to_db scheduled__2024-06-25T12:00:00+00:00 [running]> on host ad6ccfebc5a6
[2024-06-26T01:24:15.287+0000] {taskinstance.py:2648} INFO - Exporting env vars: AIRFLOW_CTX_DAG_OWNER='airflow' AIRFLOW_CTX_DAG_ID='create_movie_dataset_v7' AIRFLOW_CTX_TASK_ID='insert_data_to_db' AIRFLOW_CTX_EXECUTION_DATE='2024-06-25T12:00:00+00:00' AIRFLOW_CTX_TRY_NUMBER='1' AIRFLOW_CTX_DAG_RUN_ID='scheduled__2024-06-25T12:00:00+00:00'
[2024-06-26T01:24:15.301+0000] {taskinstance.py:430} INFO - ::endgroup::
[2024-06-26T01:24:15.311+0000] {logging_mixin.py:188} INFO - CREATE TABLE IF NOT EXISTS movies (
            id SERIAL PRIMARY KEY,
            name VARCHAR,
            description VARCHAR,
            year INTEGER,
            rating FLOAT,
            votes INTEGER,
            movie_length INTEGER,
            age_rating VARCHAR,
            genres VARCHAR,
            countries VARCHAR
        )
[2024-06-26T01:24:15.317+0000] {base.py:84} INFO - Using connection ID 'postgres' for task execution.
[2024-06-26T01:24:15.372+0000] {logging_mixin.py:188} INFO - INSERT INTO movies (name, description, year, rating, votes, movie_length, age_rating, genres, countries)
            VALUES (%s, %s, %s, %s, %s, %s, %s, %s, %s)
[2024-06-26T01:24:15.386+0000] {base.py:84} INFO - Using connection ID 'postgres' for task execution.
[2024-06-26T01:24:15.426+0000] {taskinstance.py:441} INFO - ::group::Post task execution logs
[2024-06-26T01:24:15.427+0000] {taskinstance.py:2905} ERROR - Task failed with exception
Traceback (most recent call last):
  File "/home/airflow/.local/lib/python3.12/site-packages/airflow/models/taskinstance.py", line 465, in _execute_task
    result = _execute_callable(context=context, **execute_callable_kwargs)
             ^^^^^^^^^^^^^^^^^^^^^^^^^^^^^^^^^^^^^^^^^^^^^^^^^^^^^^^^^^^^^
  File "/home/airflow/.local/lib/python3.12/site-packages/airflow/models/taskinstance.py", line 432, in _execute_callable
    return execute_callable(context=context, **execute_callable_kwargs)
           ^^^^^^^^^^^^^^^^^^^^^^^^^^^^^^^^^^^^^^^^^^^^^^^^^^^^^^^^^^^^
  File "/home/airflow/.local/lib/python3.12/site-packages/airflow/models/baseoperator.py", line 400, in wrapper
    return func(self, *args, **kwargs)
           ^^^^^^^^^^^^^^^^^^^^^^^^^^^
  File "/home/airflow/.local/lib/python3.12/site-packages/airflow/operators/python.py", line 235, in execute
    return_value = self.execute_callable()
                   ^^^^^^^^^^^^^^^^^^^^^^^
  File "/home/airflow/.local/lib/python3.12/site-packages/airflow/operators/python.py", line 252, in execute_callable
    return self.python_callable(*self.op_args, **self.op_kwargs)
           ^^^^^^^^^^^^^^^^^^^^^^^^^^^^^^^^^^^^^^^^^^^^^^^^^^^^^
  File "/opt/airflow/dags/tasks/insert_data_to_db.py", line 25, in insert_data_to_db
    hook.get_conn().cursor().execute(insert_query, values)
psycopg2.errors.UndefinedTable: ОШИБКА:  отношение "movies" не существует
LINE 1: INSERT INTO movies (name, description, year, rating, votes, ...
                    ^

[2024-06-26T01:24:15.436+0000] {taskinstance.py:1206} INFO - Marking task as UP_FOR_RETRY. dag_id=create_movie_dataset_v7, task_id=insert_data_to_db, run_id=scheduled__2024-06-25T12:00:00+00:00, execution_date=20240625T120000, start_date=20240626T012415, end_date=20240626T012415
[2024-06-26T01:24:15.444+0000] {standard_task_runner.py:110} ERROR - Failed to execute job 86 for task insert_data_to_db (ОШИБКА:  отношение "movies" не существует
LINE 1: INSERT INTO movies (name, description, year, rating, votes, ...
                    ^
; 2789)
[2024-06-26T01:24:15.451+0000] {local_task_job_runner.py:240} INFO - Task exited with return code 1
[2024-06-26T01:24:15.462+0000] {taskinstance.py:3498} INFO - 0 downstream tasks scheduled from follow-on schedule check
[2024-06-26T01:24:15.465+0000] {local_task_job_runner.py:222} INFO - ::endgroup::
