[2024-07-01T00:25:41.734+0000] {local_task_job_runner.py:120} INFO - ::group::Pre task execution logs
[2024-07-01T00:25:41.748+0000] {taskinstance.py:2076} INFO - Dependencies all met for dep_context=non-requeueable deps ti=<TaskInstance: model_training_v6.train_model scheduled__2024-06-30T00:00:00+00:00 [queued]>
[2024-07-01T00:25:41.752+0000] {taskinstance.py:2076} INFO - Dependencies all met for dep_context=requeueable deps ti=<TaskInstance: model_training_v6.train_model scheduled__2024-06-30T00:00:00+00:00 [queued]>
[2024-07-01T00:25:41.753+0000] {taskinstance.py:2306} INFO - Starting attempt 1 of 2
[2024-07-01T00:25:41.764+0000] {taskinstance.py:2330} INFO - Executing <Task(PythonOperator): train_model> on 2024-06-30 00:00:00+00:00
[2024-07-01T00:25:41.770+0000] {warnings.py:110} WARNING - /home/airflow/.local/lib/python3.12/site-packages/airflow/task/task_runner/standard_task_runner.py:61: DeprecationWarning: This process (pid=422) is multi-threaded, use of fork() may lead to deadlocks in the child.
  pid = os.fork()

[2024-07-01T00:25:41.771+0000] {standard_task_runner.py:63} INFO - Started process 444 to run task
[2024-07-01T00:25:41.770+0000] {standard_task_runner.py:90} INFO - Running: ['airflow', 'tasks', 'run', 'model_training_v6', 'train_model', 'scheduled__2024-06-30T00:00:00+00:00', '--job-id', '679', '--raw', '--subdir', 'DAGS_FOLDER/model_training.py', '--cfg-path', '/tmp/tmp9q5gr0lv']
[2024-07-01T00:25:41.772+0000] {standard_task_runner.py:91} INFO - Job 679: Subtask train_model
[2024-07-01T00:25:41.806+0000] {task_command.py:426} INFO - Running <TaskInstance: model_training_v6.train_model scheduled__2024-06-30T00:00:00+00:00 [running]> on host 52eea2daf696
[2024-07-01T00:25:41.861+0000] {taskinstance.py:2648} INFO - Exporting env vars: AIRFLOW_CTX_DAG_OWNER='airflow' AIRFLOW_CTX_DAG_ID='model_training_v6' AIRFLOW_CTX_TASK_ID='train_model' AIRFLOW_CTX_EXECUTION_DATE='2024-06-30T00:00:00+00:00' AIRFLOW_CTX_TRY_NUMBER='1' AIRFLOW_CTX_DAG_RUN_ID='scheduled__2024-06-30T00:00:00+00:00'
[2024-07-01T00:25:41.861+0000] {taskinstance.py:430} INFO - ::endgroup::
[2024-07-01T00:25:41.977+0000] {logging_mixin.py:188} WARNING - 2024/07/01 00:25:41 WARNING mlflow.utils.git_utils: Failed to import Git (the Git executable is probably not on your PATH), so Git SHA is not available. Error: Failed to initialize: Bad git executable.
The git executable must be specified in one of the following ways:
    - be included in your $PATH
    - be set via $GIT_PYTHON_GIT_EXECUTABLE
    - explicitly set via git.refresh(<full-path-to-git-executable>)

All git commands will error until this is rectified.

This initial message can be silenced or aggravated in the future by setting the
$GIT_PYTHON_REFRESH environment variable. Use one of the following values:
    - quiet|q|silence|s|silent|none|n|0: for no message or exception
    - warn|w|warning|log|l|1: for a warning message (logging level CRITICAL, displayed by default)
    - error|e|exception|raise|r|2: for a raised exception

Example:
    export GIT_PYTHON_REFRESH=quiet
[2024-07-01T00:25:44.762+0000] {taskinstance.py:441} INFO - ::group::Post task execution logs
[2024-07-01T00:25:44.763+0000] {taskinstance.py:2905} ERROR - Task failed with exception
Traceback (most recent call last):
  File "/home/airflow/.local/lib/python3.12/site-packages/airflow/models/taskinstance.py", line 465, in _execute_task
    result = _execute_callable(context=context, **execute_callable_kwargs)
             ^^^^^^^^^^^^^^^^^^^^^^^^^^^^^^^^^^^^^^^^^^^^^^^^^^^^^^^^^^^^^
  File "/home/airflow/.local/lib/python3.12/site-packages/airflow/models/taskinstance.py", line 432, in _execute_callable
    return execute_callable(context=context, **execute_callable_kwargs)
           ^^^^^^^^^^^^^^^^^^^^^^^^^^^^^^^^^^^^^^^^^^^^^^^^^^^^^^^^^^^^
  File "/home/airflow/.local/lib/python3.12/site-packages/airflow/models/baseoperator.py", line 400, in wrapper
    return func(self, *args, **kwargs)
           ^^^^^^^^^^^^^^^^^^^^^^^^^^^
  File "/home/airflow/.local/lib/python3.12/site-packages/airflow/operators/python.py", line 235, in execute
    return_value = self.execute_callable()
                   ^^^^^^^^^^^^^^^^^^^^^^^
  File "/home/airflow/.local/lib/python3.12/site-packages/airflow/operators/python.py", line 252, in execute_callable
    return self.python_callable(*self.op_args, **self.op_kwargs)
           ^^^^^^^^^^^^^^^^^^^^^^^^^^^^^^^^^^^^^^^^^^^^^^^^^^^^^
  File "/opt/airflow/dags/model_training.py", line 70, in train_model
    mlflow.pyfunc.save_model(path=model_path, python_model=clf)
  File "/home/airflow/.local/lib/python3.12/site-packages/mlflow/tracing/provider.py", line 251, in wrapper
    return f(*args, **kwargs)
           ^^^^^^^^^^^^^^^^^^
  File "/home/airflow/.local/lib/python3.12/site-packages/mlflow/pyfunc/__init__.py", line 2354, in save_model
    _validate_function_python_model(python_model)
  File "/home/airflow/.local/lib/python3.12/site-packages/mlflow/pyfunc/__init__.py", line 2148, in _validate_function_python_model
    raise MlflowException(
mlflow.exceptions.MlflowException: `python_model` must be a PythonModel instance, callable object, or path to a script that uses set_model() to set a PythonModel instance or callable object.
[2024-07-01T00:25:44.772+0000] {taskinstance.py:1206} INFO - Marking task as UP_FOR_RETRY. dag_id=model_training_v6, task_id=train_model, run_id=scheduled__2024-06-30T00:00:00+00:00, execution_date=20240630T000000, start_date=20240701T002541, end_date=20240701T002544
[2024-07-01T00:25:44.782+0000] {standard_task_runner.py:110} ERROR - Failed to execute job 679 for task train_model (`python_model` must be a PythonModel instance, callable object, or path to a script that uses set_model() to set a PythonModel instance or callable object.; 444)
[2024-07-01T00:25:44.792+0000] {local_task_job_runner.py:240} INFO - Task exited with return code 1
[2024-07-01T00:25:44.846+0000] {taskinstance.py:3498} INFO - 0 downstream tasks scheduled from follow-on schedule check
[2024-07-01T00:25:44.849+0000] {local_task_job_runner.py:222} INFO - ::endgroup::
