[2024-07-06T03:13:17.500+0000] {local_task_job_runner.py:120} INFO - ::group::Pre task execution logs
[2024-07-06T03:13:17.509+0000] {taskinstance.py:2076} INFO - Dependencies all met for dep_context=non-requeueable deps ti=<TaskInstance: model_training_v37.create_bucket scheduled__2024-07-05T00:00:00+00:00 [queued]>
[2024-07-06T03:13:17.514+0000] {taskinstance.py:2076} INFO - Dependencies all met for dep_context=requeueable deps ti=<TaskInstance: model_training_v37.create_bucket scheduled__2024-07-05T00:00:00+00:00 [queued]>
[2024-07-06T03:13:17.514+0000] {taskinstance.py:2306} INFO - Starting attempt 2 of 2
[2024-07-06T03:13:17.524+0000] {taskinstance.py:2330} INFO - Executing <Task(PythonOperator): create_bucket> on 2024-07-05 00:00:00+00:00
[2024-07-06T03:13:17.529+0000] {warnings.py:110} WARNING - /home/airflow/.local/lib/python3.12/site-packages/airflow/task/task_runner/standard_task_runner.py:61: DeprecationWarning: This process (pid=4132) is multi-threaded, use of fork() may lead to deadlocks in the child.
  pid = os.fork()

[2024-07-06T03:13:17.530+0000] {standard_task_runner.py:63} INFO - Started process 4160 to run task
[2024-07-06T03:13:17.530+0000] {standard_task_runner.py:90} INFO - Running: ['airflow', 'tasks', 'run', 'model_training_v37', 'create_bucket', 'scheduled__2024-07-05T00:00:00+00:00', '--job-id', '30', '--raw', '--subdir', 'DAGS_FOLDER/model_training.py', '--cfg-path', '/tmp/tmpen0wb78c']
[2024-07-06T03:13:17.538+0000] {standard_task_runner.py:91} INFO - Job 30: Subtask create_bucket
[2024-07-06T03:13:17.570+0000] {task_command.py:426} INFO - Running <TaskInstance: model_training_v37.create_bucket scheduled__2024-07-05T00:00:00+00:00 [running]> on host fba33172adc1
[2024-07-06T03:13:17.618+0000] {taskinstance.py:2648} INFO - Exporting env vars: AIRFLOW_CTX_DAG_OWNER='airflow' AIRFLOW_CTX_DAG_ID='model_training_v37' AIRFLOW_CTX_TASK_ID='create_bucket' AIRFLOW_CTX_EXECUTION_DATE='2024-07-05T00:00:00+00:00' AIRFLOW_CTX_TRY_NUMBER='2' AIRFLOW_CTX_DAG_RUN_ID='scheduled__2024-07-05T00:00:00+00:00'
[2024-07-06T03:13:17.619+0000] {taskinstance.py:430} INFO - ::endgroup::
[2024-07-06T03:13:17.633+0000] {base.py:84} INFO - Using connection ID 'minio' for task execution.
[2024-07-06T03:13:17.633+0000] {connection_wrapper.py:384} INFO - AWS Connection (conn_id='minio', conn_type='aws') credentials retrieved from login and password.
[2024-07-06T03:13:18.608+0000] {taskinstance.py:441} INFO - ::group::Post task execution logs
[2024-07-06T03:13:18.608+0000] {taskinstance.py:2905} ERROR - Task failed with exception
Traceback (most recent call last):
  File "/home/airflow/.local/lib/python3.12/site-packages/airflow/models/taskinstance.py", line 465, in _execute_task
    result = _execute_callable(context=context, **execute_callable_kwargs)
             ^^^^^^^^^^^^^^^^^^^^^^^^^^^^^^^^^^^^^^^^^^^^^^^^^^^^^^^^^^^^^
  File "/home/airflow/.local/lib/python3.12/site-packages/airflow/models/taskinstance.py", line 432, in _execute_callable
    return execute_callable(context=context, **execute_callable_kwargs)
           ^^^^^^^^^^^^^^^^^^^^^^^^^^^^^^^^^^^^^^^^^^^^^^^^^^^^^^^^^^^^
  File "/home/airflow/.local/lib/python3.12/site-packages/airflow/models/baseoperator.py", line 400, in wrapper
    return func(self, *args, **kwargs)
           ^^^^^^^^^^^^^^^^^^^^^^^^^^^
  File "/home/airflow/.local/lib/python3.12/site-packages/airflow/operators/python.py", line 235, in execute
    return_value = self.execute_callable()
                   ^^^^^^^^^^^^^^^^^^^^^^^
  File "/home/airflow/.local/lib/python3.12/site-packages/airflow/operators/python.py", line 252, in execute_callable
    return self.python_callable(*self.op_args, **self.op_kwargs)
           ^^^^^^^^^^^^^^^^^^^^^^^^^^^^^^^^^^^^^^^^^^^^^^^^^^^^^
  File "/opt/airflow/dags/tasks/create_bucket.py", line 11, in create_bucket
    hook.create_bucket(bucket_name=bucket_name)
  File "/home/airflow/.local/lib/python3.12/site-packages/airflow/providers/amazon/aws/hooks/s3.py", line 89, in wrapper
    return func(*bound_args.args, **bound_args.kwargs)
           ^^^^^^^^^^^^^^^^^^^^^^^^^^^^^^^^^^^^^^^^^^^
  File "/home/airflow/.local/lib/python3.12/site-packages/airflow/providers/amazon/aws/hooks/s3.py", line 339, in create_bucket
    self.get_conn().create_bucket(Bucket=bucket_name)
  File "/home/airflow/.local/lib/python3.12/site-packages/botocore/client.py", line 553, in _api_call
    return self._make_api_call(operation_name, kwargs)
           ^^^^^^^^^^^^^^^^^^^^^^^^^^^^^^^^^^^^^^^^^^^
  File "/home/airflow/.local/lib/python3.12/site-packages/botocore/client.py", line 1009, in _make_api_call
    raise error_class(parsed_response, operation_name)
botocore.exceptions.ClientError: An error occurred (InvalidAccessKeyId) when calling the CreateBucket operation: The AWS Access Key Id you provided does not exist in our records.
[2024-07-06T03:13:18.616+0000] {taskinstance.py:1206} INFO - Marking task as FAILED. dag_id=model_training_v37, task_id=create_bucket, run_id=scheduled__2024-07-05T00:00:00+00:00, execution_date=20240705T000000, start_date=20240706T031317, end_date=20240706T031318
[2024-07-06T03:13:18.625+0000] {standard_task_runner.py:110} ERROR - Failed to execute job 30 for task create_bucket (An error occurred (InvalidAccessKeyId) when calling the CreateBucket operation: The AWS Access Key Id you provided does not exist in our records.; 4160)
[2024-07-06T03:13:18.637+0000] {local_task_job_runner.py:240} INFO - Task exited with return code 1
[2024-07-06T03:13:18.649+0000] {taskinstance.py:3498} INFO - 0 downstream tasks scheduled from follow-on schedule check
[2024-07-06T03:13:18.652+0000] {local_task_job_runner.py:222} INFO - ::endgroup::
