[2024-07-06T02:13:32.347+0000] {local_task_job_runner.py:120} INFO - ::group::Pre task execution logs
[2024-07-06T02:13:32.361+0000] {taskinstance.py:2076} INFO - Dependencies all met for dep_context=non-requeueable deps ti=<TaskInstance: model_training_v29.create_bucket scheduled__2024-07-05T00:00:00+00:00 [queued]>
[2024-07-06T02:13:32.367+0000] {taskinstance.py:2076} INFO - Dependencies all met for dep_context=requeueable deps ti=<TaskInstance: model_training_v29.create_bucket scheduled__2024-07-05T00:00:00+00:00 [queued]>
[2024-07-06T02:13:32.368+0000] {taskinstance.py:2306} INFO - Starting attempt 1 of 2
[2024-07-06T02:13:32.377+0000] {taskinstance.py:2330} INFO - Executing <Task(PythonOperator): create_bucket> on 2024-07-05 00:00:00+00:00
[2024-07-06T02:13:32.383+0000] {warnings.py:110} WARNING - /home/airflow/.local/lib/python3.12/site-packages/airflow/task/task_runner/standard_task_runner.py:61: DeprecationWarning: This process (pid=2753) is multi-threaded, use of fork() may lead to deadlocks in the child.
  pid = os.fork()

[2024-07-06T02:13:32.384+0000] {standard_task_runner.py:63} INFO - Started process 2774 to run task
[2024-07-06T02:13:32.384+0000] {standard_task_runner.py:90} INFO - Running: ['airflow', 'tasks', 'run', 'model_training_v29', 'create_bucket', 'scheduled__2024-07-05T00:00:00+00:00', '--job-id', '18', '--raw', '--subdir', 'DAGS_FOLDER/model_training.py', '--cfg-path', '/tmp/tmpqcfsl0fu']
[2024-07-06T02:13:32.388+0000] {standard_task_runner.py:91} INFO - Job 18: Subtask create_bucket
[2024-07-06T02:13:32.422+0000] {task_command.py:426} INFO - Running <TaskInstance: model_training_v29.create_bucket scheduled__2024-07-05T00:00:00+00:00 [running]> on host a1df16e4b0a7
[2024-07-06T02:13:32.476+0000] {taskinstance.py:2648} INFO - Exporting env vars: AIRFLOW_CTX_DAG_OWNER='airflow' AIRFLOW_CTX_DAG_ID='model_training_v29' AIRFLOW_CTX_TASK_ID='create_bucket' AIRFLOW_CTX_EXECUTION_DATE='2024-07-05T00:00:00+00:00' AIRFLOW_CTX_TRY_NUMBER='1' AIRFLOW_CTX_DAG_RUN_ID='scheduled__2024-07-05T00:00:00+00:00'
[2024-07-06T02:13:32.481+0000] {taskinstance.py:430} INFO - ::endgroup::
[2024-07-06T02:13:32.499+0000] {connectionpool.py:874} WARNING - Retrying (Retry(total=4, connect=None, read=None, redirect=None, status=None)) after connection broken by 'NameResolutionError("<urllib3.connection.HTTPConnection object at 0x7fabab326ba0>: Failed to resolve 'docker.internal.host' ([Errno -2] Name or service not known)")': /my-bucket
[2024-07-06T02:13:32.903+0000] {connectionpool.py:874} WARNING - Retrying (Retry(total=3, connect=None, read=None, redirect=None, status=None)) after connection broken by 'NameResolutionError("<urllib3.connection.HTTPConnection object at 0x7fabab326e70>: Failed to resolve 'docker.internal.host' ([Errno -2] Name or service not known)")': /my-bucket
[2024-07-06T02:13:33.717+0000] {connectionpool.py:874} WARNING - Retrying (Retry(total=2, connect=None, read=None, redirect=None, status=None)) after connection broken by 'NameResolutionError("<urllib3.connection.HTTPConnection object at 0x7fabab3274a0>: Failed to resolve 'docker.internal.host' ([Errno -2] Name or service not known)")': /my-bucket
[2024-07-06T02:13:35.347+0000] {connectionpool.py:874} WARNING - Retrying (Retry(total=1, connect=None, read=None, redirect=None, status=None)) after connection broken by 'NameResolutionError("<urllib3.connection.HTTPConnection object at 0x7fabab327830>: Failed to resolve 'docker.internal.host' ([Errno -2] Name or service not known)")': /my-bucket
[2024-07-06T02:13:38.554+0000] {connectionpool.py:874} WARNING - Retrying (Retry(total=0, connect=None, read=None, redirect=None, status=None)) after connection broken by 'NameResolutionError("<urllib3.connection.HTTPConnection object at 0x7fabab327b00>: Failed to resolve 'docker.internal.host' ([Errno -2] Name or service not known)")': /my-bucket
[2024-07-06T02:13:38.562+0000] {logging_mixin.py:188} INFO - Ошибка при создании bucket 'my-bucket': HTTPConnectionPool(host='docker.internal.host', port=9000): Max retries exceeded with url: /my-bucket (Caused by NameResolutionError("<urllib3.connection.HTTPConnection object at 0x7fabab327ef0>: Failed to resolve 'docker.internal.host' ([Errno -2] Name or service not known)"))
[2024-07-06T02:13:38.563+0000] {python.py:237} INFO - Done. Returned value was: None
[2024-07-06T02:13:38.563+0000] {taskinstance.py:441} INFO - ::group::Post task execution logs
[2024-07-06T02:13:38.570+0000] {taskinstance.py:1206} INFO - Marking task as SUCCESS. dag_id=model_training_v29, task_id=create_bucket, run_id=scheduled__2024-07-05T00:00:00+00:00, execution_date=20240705T000000, start_date=20240706T021332, end_date=20240706T021338
[2024-07-06T02:13:38.610+0000] {local_task_job_runner.py:240} INFO - Task exited with return code 0
[2024-07-06T02:13:38.619+0000] {taskinstance.py:3498} INFO - 0 downstream tasks scheduled from follow-on schedule check
[2024-07-06T02:13:38.622+0000] {local_task_job_runner.py:222} INFO - ::endgroup::
