[2024-07-13T03:20:02.153+0000] {task_context_logger.py:104} ERROR - Executor reports task instance <TaskInstance: model_training_v90.create_bucket scheduled__2024-07-13T03:15:00+00:00 [queued]> finished (failed) although the task says it's queued. (Info: None) Was the task killed externally?
