[2024-07-11T03:18:03.443+0000] {local_task_job_runner.py:120} INFO - ::group::Pre task execution logs
[2024-07-11T03:18:03.453+0000] {taskinstance.py:2076} INFO - Dependencies all met for dep_context=non-requeueable deps ti=<TaskInstance: model_training_v83.create_experiment scheduled__2024-07-10T00:00:00+00:00 [queued]>
[2024-07-11T03:18:03.458+0000] {taskinstance.py:2076} INFO - Dependencies all met for dep_context=requeueable deps ti=<TaskInstance: model_training_v83.create_experiment scheduled__2024-07-10T00:00:00+00:00 [queued]>
[2024-07-11T03:18:03.458+0000] {taskinstance.py:2306} INFO - Starting attempt 1 of 2
[2024-07-11T03:18:03.473+0000] {taskinstance.py:2330} INFO - Executing <Task(PythonOperator): create_experiment> on 2024-07-10 00:00:00+00:00
[2024-07-11T03:18:03.479+0000] {warnings.py:110} WARNING - /home/airflow/.local/lib/python3.12/site-packages/airflow/task/task_runner/standard_task_runner.py:61: DeprecationWarning: This process (pid=397) is multi-threaded, use of fork() may lead to deadlocks in the child.
  pid = os.fork()

[2024-07-11T03:18:03.480+0000] {standard_task_runner.py:63} INFO - Started process 439 to run task
[2024-07-11T03:18:03.480+0000] {standard_task_runner.py:90} INFO - Running: ['airflow', 'tasks', 'run', 'model_training_v83', 'create_experiment', 'scheduled__2024-07-10T00:00:00+00:00', '--job-id', '288', '--raw', '--subdir', 'DAGS_FOLDER/model_training.py', '--cfg-path', '/tmp/tmp498th2q4']
[2024-07-11T03:18:03.481+0000] {standard_task_runner.py:91} INFO - Job 288: Subtask create_experiment
[2024-07-11T03:18:03.513+0000] {task_command.py:426} INFO - Running <TaskInstance: model_training_v83.create_experiment scheduled__2024-07-10T00:00:00+00:00 [running]> on host ab430778e8ff
[2024-07-11T03:18:03.569+0000] {taskinstance.py:2648} INFO - Exporting env vars: AIRFLOW_CTX_DAG_OWNER='airflow' AIRFLOW_CTX_DAG_ID='model_training_v83' AIRFLOW_CTX_TASK_ID='create_experiment' AIRFLOW_CTX_EXECUTION_DATE='2024-07-10T00:00:00+00:00' AIRFLOW_CTX_TRY_NUMBER='1' AIRFLOW_CTX_DAG_RUN_ID='scheduled__2024-07-10T00:00:00+00:00'
[2024-07-11T03:18:03.571+0000] {taskinstance.py:430} INFO - ::endgroup::
[2024-07-11T03:18:03.658+0000] {logging_mixin.py:188} WARNING - 2024/07/11 03:18:03 WARNING mlflow.store.db.utils: SQLAlchemy engine could not be created. The following exception is caught.
(psycopg2.OperationalError) connection to server at "172.17.0.1", port 5432 failed: FATAL:  database "mlflow" does not exist

(Background on this error at: https://sqlalche.me/e/14/e3q8)
Operation will be retried in 0.1 seconds
[2024-07-11T03:18:03.762+0000] {logging_mixin.py:188} WARNING - 2024/07/11 03:18:03 WARNING mlflow.store.db.utils: SQLAlchemy engine could not be created. The following exception is caught.
(psycopg2.OperationalError) connection to server at "172.17.0.1", port 5432 failed: FATAL:  database "mlflow" does not exist

(Background on this error at: https://sqlalche.me/e/14/e3q8)
Operation will be retried in 0.3 seconds
[2024-07-11T03:18:04.065+0000] {logging_mixin.py:188} WARNING - 2024/07/11 03:18:04 WARNING mlflow.store.db.utils: SQLAlchemy engine could not be created. The following exception is caught.
(psycopg2.OperationalError) connection to server at "172.17.0.1", port 5432 failed: FATAL:  database "mlflow" does not exist

(Background on this error at: https://sqlalche.me/e/14/e3q8)
Operation will be retried in 0.7 seconds
[2024-07-11T03:18:04.770+0000] {logging_mixin.py:188} WARNING - 2024/07/11 03:18:04 WARNING mlflow.store.db.utils: SQLAlchemy engine could not be created. The following exception is caught.
(psycopg2.OperationalError) connection to server at "172.17.0.1", port 5432 failed: FATAL:  database "mlflow" does not exist

(Background on this error at: https://sqlalche.me/e/14/e3q8)
Operation will be retried in 1.5 seconds
[2024-07-11T03:18:06.273+0000] {logging_mixin.py:188} WARNING - 2024/07/11 03:18:06 WARNING mlflow.store.db.utils: SQLAlchemy engine could not be created. The following exception is caught.
(psycopg2.OperationalError) connection to server at "172.17.0.1", port 5432 failed: FATAL:  database "mlflow" does not exist

(Background on this error at: https://sqlalche.me/e/14/e3q8)
Operation will be retried in 3.1 seconds
[2024-07-11T03:18:09.378+0000] {logging_mixin.py:188} WARNING - 2024/07/11 03:18:09 WARNING mlflow.store.db.utils: SQLAlchemy engine could not be created. The following exception is caught.
(psycopg2.OperationalError) connection to server at "172.17.0.1", port 5432 failed: FATAL:  database "mlflow" does not exist

(Background on this error at: https://sqlalche.me/e/14/e3q8)
Operation will be retried in 6.3 seconds
[2024-07-11T03:18:15.681+0000] {logging_mixin.py:188} WARNING - 2024/07/11 03:18:15 WARNING mlflow.store.db.utils: SQLAlchemy engine could not be created. The following exception is caught.
(psycopg2.OperationalError) connection to server at "172.17.0.1", port 5432 failed: FATAL:  database "mlflow" does not exist

(Background on this error at: https://sqlalche.me/e/14/e3q8)
Operation will be retried in 12.7 seconds
[2024-07-11T03:18:28.385+0000] {logging_mixin.py:188} WARNING - 2024/07/11 03:18:28 WARNING mlflow.store.db.utils: SQLAlchemy engine could not be created. The following exception is caught.
(psycopg2.OperationalError) connection to server at "172.17.0.1", port 5432 failed: FATAL:  database "mlflow" does not exist

(Background on this error at: https://sqlalche.me/e/14/e3q8)
Operation will be retried in 25.5 seconds
[2024-07-11T03:18:53.894+0000] {logging_mixin.py:188} WARNING - 2024/07/11 03:18:53 WARNING mlflow.store.db.utils: SQLAlchemy engine could not be created. The following exception is caught.
(psycopg2.OperationalError) connection to server at "172.17.0.1", port 5432 failed: FATAL:  database "mlflow" does not exist

(Background on this error at: https://sqlalche.me/e/14/e3q8)
Operation will be retried in 51.1 seconds
[2024-07-11T03:19:44.997+0000] {logging_mixin.py:188} WARNING - 2024/07/11 03:19:44 WARNING mlflow.store.db.utils: SQLAlchemy engine could not be created. The following exception is caught.
(psycopg2.OperationalError) connection to server at "172.17.0.1", port 5432 failed: FATAL:  database "mlflow" does not exist

(Background on this error at: https://sqlalche.me/e/14/e3q8)
Operation will be retried in 102.3 seconds
[2024-07-11T03:21:27.299+0000] {logging_mixin.py:188} WARNING - 2024/07/11 03:21:27 WARNING mlflow.store.db.utils: SQLAlchemy engine could not be created. The following exception is caught.
(psycopg2.OperationalError) connection to server at "172.17.0.1", port 5432 failed: FATAL:  database "mlflow" does not exist

(Background on this error at: https://sqlalche.me/e/14/e3q8)
Operation will be retried in 204.7 seconds
[2024-07-11T03:24:52.000+0000] {logging_mixin.py:188} WARNING - 2024/07/11 03:24:52 WARNING mlflow.store.db.utils: SQLAlchemy engine could not be created. The following exception is caught.
(psycopg2.OperationalError) connection to server at "172.17.0.1", port 5432 failed: FATAL:  database "mlflow" does not exist

(Background on this error at: https://sqlalche.me/e/14/e3q8)
Operation will be retried in 409.5 seconds
[2024-07-11T03:31:41.493+0000] {logging_mixin.py:188} WARNING - 2024/07/11 03:31:41 WARNING mlflow.store.db.utils: SQLAlchemy engine could not be created. The following exception is caught.
(psycopg2.OperationalError) connection to server at "172.17.0.1", port 5432 failed: FATAL:  database "mlflow" does not exist

(Background on this error at: https://sqlalche.me/e/14/e3q8)
Operation will be retried in 819.1 seconds
[2024-07-11T03:45:20.579+0000] {logging_mixin.py:188} WARNING - 2024/07/11 03:45:20 WARNING mlflow.store.db.utils: SQLAlchemy engine could not be created. The following exception is caught.
(psycopg2.OperationalError) connection to server at "172.17.0.1", port 5432 failed: FATAL:  database "mlflow" does not exist

(Background on this error at: https://sqlalche.me/e/14/e3q8)
Operation will be retried in 1638.3 seconds
[2024-07-11T04:12:38.827+0000] {taskinstance.py:441} INFO - ::group::Post task execution logs
[2024-07-11T04:12:38.828+0000] {taskinstance.py:2905} ERROR - Task failed with exception
Traceback (most recent call last):
  File "/home/airflow/.local/lib/python3.12/site-packages/sqlalchemy/engine/base.py", line 3371, in _wrap_pool_connect
    return fn()
           ^^^^
  File "/home/airflow/.local/lib/python3.12/site-packages/sqlalchemy/pool/base.py", line 327, in connect
    return _ConnectionFairy._checkout(self)
           ^^^^^^^^^^^^^^^^^^^^^^^^^^^^^^^^
  File "/home/airflow/.local/lib/python3.12/site-packages/sqlalchemy/pool/base.py", line 894, in _checkout
    fairy = _ConnectionRecord.checkout(pool)
            ^^^^^^^^^^^^^^^^^^^^^^^^^^^^^^^^
  File "/home/airflow/.local/lib/python3.12/site-packages/sqlalchemy/pool/base.py", line 493, in checkout
    rec = pool._do_get()
          ^^^^^^^^^^^^^^
  File "/home/airflow/.local/lib/python3.12/site-packages/sqlalchemy/pool/impl.py", line 145, in _do_get
    with util.safe_reraise():
  File "/home/airflow/.local/lib/python3.12/site-packages/sqlalchemy/util/langhelpers.py", line 70, in __exit__
    compat.raise_(
  File "/home/airflow/.local/lib/python3.12/site-packages/sqlalchemy/util/compat.py", line 211, in raise_
    raise exception
  File "/home/airflow/.local/lib/python3.12/site-packages/sqlalchemy/pool/impl.py", line 143, in _do_get
    return self._create_connection()
           ^^^^^^^^^^^^^^^^^^^^^^^^^
  File "/home/airflow/.local/lib/python3.12/site-packages/sqlalchemy/pool/base.py", line 273, in _create_connection
    return _ConnectionRecord(self)
           ^^^^^^^^^^^^^^^^^^^^^^^
  File "/home/airflow/.local/lib/python3.12/site-packages/sqlalchemy/pool/base.py", line 388, in __init__
    self.__connect()
  File "/home/airflow/.local/lib/python3.12/site-packages/sqlalchemy/pool/base.py", line 690, in __connect
    with util.safe_reraise():
  File "/home/airflow/.local/lib/python3.12/site-packages/sqlalchemy/util/langhelpers.py", line 70, in __exit__
    compat.raise_(
  File "/home/airflow/.local/lib/python3.12/site-packages/sqlalchemy/util/compat.py", line 211, in raise_
    raise exception
  File "/home/airflow/.local/lib/python3.12/site-packages/sqlalchemy/pool/base.py", line 686, in __connect
    self.dbapi_connection = connection = pool._invoke_creator(self)
                                         ^^^^^^^^^^^^^^^^^^^^^^^^^^
  File "/home/airflow/.local/lib/python3.12/site-packages/sqlalchemy/engine/create.py", line 574, in connect
    return dialect.connect(*cargs, **cparams)
           ^^^^^^^^^^^^^^^^^^^^^^^^^^^^^^^^^^
  File "/home/airflow/.local/lib/python3.12/site-packages/sqlalchemy/engine/default.py", line 598, in connect
    return self.dbapi.connect(*cargs, **cparams)
           ^^^^^^^^^^^^^^^^^^^^^^^^^^^^^^^^^^^^^
  File "/home/airflow/.local/lib/python3.12/site-packages/psycopg2/__init__.py", line 122, in connect
    conn = _connect(dsn, connection_factory=connection_factory, **kwasync)
           ^^^^^^^^^^^^^^^^^^^^^^^^^^^^^^^^^^^^^^^^^^^^^^^^^^^^^^^^^^^^^^^
psycopg2.OperationalError: connection to server at "172.17.0.1", port 5432 failed: FATAL:  database "mlflow" does not exist


The above exception was the direct cause of the following exception:

Traceback (most recent call last):
  File "/home/airflow/.local/lib/python3.12/site-packages/airflow/models/taskinstance.py", line 465, in _execute_task
    result = _execute_callable(context=context, **execute_callable_kwargs)
             ^^^^^^^^^^^^^^^^^^^^^^^^^^^^^^^^^^^^^^^^^^^^^^^^^^^^^^^^^^^^^
  File "/home/airflow/.local/lib/python3.12/site-packages/airflow/models/taskinstance.py", line 432, in _execute_callable
    return execute_callable(context=context, **execute_callable_kwargs)
           ^^^^^^^^^^^^^^^^^^^^^^^^^^^^^^^^^^^^^^^^^^^^^^^^^^^^^^^^^^^^
  File "/home/airflow/.local/lib/python3.12/site-packages/airflow/models/baseoperator.py", line 400, in wrapper
    return func(self, *args, **kwargs)
           ^^^^^^^^^^^^^^^^^^^^^^^^^^^
  File "/home/airflow/.local/lib/python3.12/site-packages/airflow/operators/python.py", line 235, in execute
    return_value = self.execute_callable()
                   ^^^^^^^^^^^^^^^^^^^^^^^
  File "/home/airflow/.local/lib/python3.12/site-packages/airflow/operators/python.py", line 252, in execute_callable
    return self.python_callable(*self.op_args, **self.op_kwargs)
           ^^^^^^^^^^^^^^^^^^^^^^^^^^^^^^^^^^^^^^^^^^^^^^^^^^^^^
  File "/opt/airflow/dags/tasks/create_experiment.py", line 14, in create_experiment
  File "/home/airflow/.local/lib/python3.12/site-packages/mlflow/tracking/fluent.py", line 1725, in create_experiment
    return MlflowClient().create_experiment(name, artifact_location, tags)
           ^^^^^^^^^^^^^^
  File "/home/airflow/.local/lib/python3.12/site-packages/mlflow/tracking/client.py", line 134, in __init__
    self._tracking_client = TrackingServiceClient(final_tracking_uri)
                            ^^^^^^^^^^^^^^^^^^^^^^^^^^^^^^^^^^^^^^^^^
  File "/home/airflow/.local/lib/python3.12/site-packages/mlflow/tracking/_tracking_service/client.py", line 79, in __init__
    self.store
  File "/home/airflow/.local/lib/python3.12/site-packages/mlflow/tracking/_tracking_service/client.py", line 83, in store
    return utils._get_store(self.tracking_uri)
           ^^^^^^^^^^^^^^^^^^^^^^^^^^^^^^^^^^^
  File "/home/airflow/.local/lib/python3.12/site-packages/mlflow/tracking/_tracking_service/utils.py", line 205, in _get_store
    return _tracking_store_registry.get_store(store_uri, artifact_uri)
           ^^^^^^^^^^^^^^^^^^^^^^^^^^^^^^^^^^^^^^^^^^^^^^^^^^^^^^^^^^^
  File "/home/airflow/.local/lib/python3.12/site-packages/mlflow/tracking/_tracking_service/registry.py", line 42, in get_store
    return self._get_store_with_resolved_uri(resolved_store_uri, artifact_uri)
           ^^^^^^^^^^^^^^^^^^^^^^^^^^^^^^^^^^^^^^^^^^^^^^^^^^^^^^^^^^^^^^^^^^^
  File "/home/airflow/.local/lib/python3.12/site-packages/mlflow/tracking/_tracking_service/registry.py", line 52, in _get_store_with_resolved_uri
    return builder(store_uri=resolved_store_uri, artifact_uri=artifact_uri)
           ^^^^^^^^^^^^^^^^^^^^^^^^^^^^^^^^^^^^^^^^^^^^^^^^^^^^^^^^^^^^^^^^
  File "/home/airflow/.local/lib/python3.12/site-packages/mlflow/tracking/_tracking_service/utils.py", line 138, in _get_sqlalchemy_store
    return SqlAlchemyStore(store_uri, artifact_uri)
           ^^^^^^^^^^^^^^^^^^^^^^^^^^^^^^^^^^^^^^^^
  File "/home/airflow/.local/lib/python3.12/site-packages/mlflow/store/tracking/sqlalchemy_store.py", line 164, in __init__
    ] = mlflow.store.db.utils.create_sqlalchemy_engine_with_retry(db_uri)
        ^^^^^^^^^^^^^^^^^^^^^^^^^^^^^^^^^^^^^^^^^^^^^^^^^^^^^^^^^^^^^^^^^
  File "/home/airflow/.local/lib/python3.12/site-packages/mlflow/store/db/utils.py", line 238, in create_sqlalchemy_engine_with_retry
    sqlalchemy.inspect(engine)
  File "/home/airflow/.local/lib/python3.12/site-packages/sqlalchemy/inspection.py", line 64, in inspect
    ret = reg(subject)
          ^^^^^^^^^^^^
  File "/home/airflow/.local/lib/python3.12/site-packages/sqlalchemy/engine/reflection.py", line 182, in _engine_insp
    return Inspector._construct(Inspector._init_engine, bind)
           ^^^^^^^^^^^^^^^^^^^^^^^^^^^^^^^^^^^^^^^^^^^^^^^^^^
  File "/home/airflow/.local/lib/python3.12/site-packages/sqlalchemy/engine/reflection.py", line 117, in _construct
    init(self, bind)
  File "/home/airflow/.local/lib/python3.12/site-packages/sqlalchemy/engine/reflection.py", line 128, in _init_engine
    engine.connect().close()
    ^^^^^^^^^^^^^^^^
  File "/home/airflow/.local/lib/python3.12/site-packages/sqlalchemy/engine/base.py", line 3325, in connect
    return self._connection_cls(self, close_with_result=close_with_result)
           ^^^^^^^^^^^^^^^^^^^^^^^^^^^^^^^^^^^^^^^^^^^^^^^^^^^^^^^^^^^^^^^
  File "/home/airflow/.local/lib/python3.12/site-packages/sqlalchemy/engine/base.py", line 96, in __init__
    else engine.raw_connection()
         ^^^^^^^^^^^^^^^^^^^^^^^
  File "/home/airflow/.local/lib/python3.12/site-packages/sqlalchemy/engine/base.py", line 3404, in raw_connection
    return self._wrap_pool_connect(self.pool.connect, _connection)
           ^^^^^^^^^^^^^^^^^^^^^^^^^^^^^^^^^^^^^^^^^^^^^^^^^^^^^^^
  File "/home/airflow/.local/lib/python3.12/site-packages/sqlalchemy/engine/base.py", line 3374, in _wrap_pool_connect
    Connection._handle_dbapi_exception_noconnection(
  File "/home/airflow/.local/lib/python3.12/site-packages/sqlalchemy/engine/base.py", line 2208, in _handle_dbapi_exception_noconnection
    util.raise_(
  File "/home/airflow/.local/lib/python3.12/site-packages/sqlalchemy/util/compat.py", line 211, in raise_
    raise exception
  File "/home/airflow/.local/lib/python3.12/site-packages/sqlalchemy/engine/base.py", line 3371, in _wrap_pool_connect
    return fn()
           ^^^^
  File "/home/airflow/.local/lib/python3.12/site-packages/sqlalchemy/pool/base.py", line 327, in connect
    return _ConnectionFairy._checkout(self)
           ^^^^^^^^^^^^^^^^^^^^^^^^^^^^^^^^
  File "/home/airflow/.local/lib/python3.12/site-packages/sqlalchemy/pool/base.py", line 894, in _checkout
    fairy = _ConnectionRecord.checkout(pool)
            ^^^^^^^^^^^^^^^^^^^^^^^^^^^^^^^^
  File "/home/airflow/.local/lib/python3.12/site-packages/sqlalchemy/pool/base.py", line 493, in checkout
    rec = pool._do_get()
          ^^^^^^^^^^^^^^
  File "/home/airflow/.local/lib/python3.12/site-packages/sqlalchemy/pool/impl.py", line 145, in _do_get
    with util.safe_reraise():
  File "/home/airflow/.local/lib/python3.12/site-packages/sqlalchemy/util/langhelpers.py", line 70, in __exit__
    compat.raise_(
  File "/home/airflow/.local/lib/python3.12/site-packages/sqlalchemy/util/compat.py", line 211, in raise_
    raise exception
  File "/home/airflow/.local/lib/python3.12/site-packages/sqlalchemy/pool/impl.py", line 143, in _do_get
    return self._create_connection()
           ^^^^^^^^^^^^^^^^^^^^^^^^^
  File "/home/airflow/.local/lib/python3.12/site-packages/sqlalchemy/pool/base.py", line 273, in _create_connection
    return _ConnectionRecord(self)
           ^^^^^^^^^^^^^^^^^^^^^^^
  File "/home/airflow/.local/lib/python3.12/site-packages/sqlalchemy/pool/base.py", line 388, in __init__
    self.__connect()
  File "/home/airflow/.local/lib/python3.12/site-packages/sqlalchemy/pool/base.py", line 690, in __connect
    with util.safe_reraise():
  File "/home/airflow/.local/lib/python3.12/site-packages/sqlalchemy/util/langhelpers.py", line 70, in __exit__
    compat.raise_(
  File "/home/airflow/.local/lib/python3.12/site-packages/sqlalchemy/util/compat.py", line 211, in raise_
    raise exception
  File "/home/airflow/.local/lib/python3.12/site-packages/sqlalchemy/pool/base.py", line 686, in __connect
    self.dbapi_connection = connection = pool._invoke_creator(self)
                                         ^^^^^^^^^^^^^^^^^^^^^^^^^^
  File "/home/airflow/.local/lib/python3.12/site-packages/sqlalchemy/engine/create.py", line 574, in connect
    return dialect.connect(*cargs, **cparams)
           ^^^^^^^^^^^^^^^^^^^^^^^^^^^^^^^^^^
  File "/home/airflow/.local/lib/python3.12/site-packages/sqlalchemy/engine/default.py", line 598, in connect
    return self.dbapi.connect(*cargs, **cparams)
           ^^^^^^^^^^^^^^^^^^^^^^^^^^^^^^^^^^^^^
  File "/home/airflow/.local/lib/python3.12/site-packages/psycopg2/__init__.py", line 122, in connect
    conn = _connect(dsn, connection_factory=connection_factory, **kwasync)
           ^^^^^^^^^^^^^^^^^^^^^^^^^^^^^^^^^^^^^^^^^^^^^^^^^^^^^^^^^^^^^^^
sqlalchemy.exc.OperationalError: (psycopg2.OperationalError) connection to server at "172.17.0.1", port 5432 failed: FATAL:  database "mlflow" does not exist

(Background on this error at: https://sqlalche.me/e/14/e3q8)
[2024-07-11T04:12:38.843+0000] {taskinstance.py:1206} INFO - Marking task as UP_FOR_RETRY. dag_id=model_training_v83, task_id=create_experiment, run_id=scheduled__2024-07-10T00:00:00+00:00, execution_date=20240710T000000, start_date=20240711T031803, end_date=20240711T041238
[2024-07-11T04:12:38.854+0000] {standard_task_runner.py:110} ERROR - Failed to execute job 288 for task create_experiment ((psycopg2.OperationalError) connection to server at "172.17.0.1", port 5432 failed: FATAL:  database "mlflow" does not exist

(Background on this error at: https://sqlalche.me/e/14/e3q8); 439)
[2024-07-11T04:12:38.864+0000] {local_task_job_runner.py:240} INFO - Task exited with return code 1
[2024-07-11T04:12:38.893+0000] {taskinstance.py:3498} INFO - 0 downstream tasks scheduled from follow-on schedule check
[2024-07-11T04:12:38.896+0000] {local_task_job_runner.py:222} INFO - ::endgroup::
