[2024-06-27T23:53:10.251+0000] {local_task_job_runner.py:120} INFO - ::group::Pre task execution logs
[2024-06-27T23:53:10.264+0000] {taskinstance.py:2076} INFO - Dependencies all met for dep_context=non-requeueable deps ti=<TaskInstance: model_training_v1.get_data scheduled__2024-06-26T00:00:00+00:00 [queued]>
[2024-06-27T23:53:10.268+0000] {taskinstance.py:2076} INFO - Dependencies all met for dep_context=requeueable deps ti=<TaskInstance: model_training_v1.get_data scheduled__2024-06-26T00:00:00+00:00 [queued]>
[2024-06-27T23:53:10.269+0000] {taskinstance.py:2306} INFO - Starting attempt 1 of 2
[2024-06-27T23:53:10.277+0000] {taskinstance.py:2330} INFO - Executing <Task(PythonOperator): get_data> on 2024-06-26 00:00:00+00:00
[2024-06-27T23:53:10.282+0000] {warnings.py:110} WARNING - /home/airflow/.local/lib/python3.12/site-packages/airflow/task/task_runner/standard_task_runner.py:61: DeprecationWarning: This process (pid=1791) is multi-threaded, use of fork() may lead to deadlocks in the child.
  pid = os.fork()

[2024-06-27T23:53:10.282+0000] {standard_task_runner.py:63} INFO - Started process 1793 to run task
[2024-06-27T23:53:10.283+0000] {standard_task_runner.py:90} INFO - Running: ['airflow', 'tasks', 'run', 'model_training_v1', 'get_data', 'scheduled__2024-06-26T00:00:00+00:00', '--job-id', '297', '--raw', '--subdir', 'DAGS_FOLDER/model_training.py', '--cfg-path', '/tmp/tmpe_y008a5']
[2024-06-27T23:53:10.284+0000] {standard_task_runner.py:91} INFO - Job 297: Subtask get_data
[2024-06-27T23:53:10.314+0000] {task_command.py:426} INFO - Running <TaskInstance: model_training_v1.get_data scheduled__2024-06-26T00:00:00+00:00 [running]> on host 36c0809852d0
[2024-06-27T23:53:10.363+0000] {taskinstance.py:2648} INFO - Exporting env vars: AIRFLOW_CTX_DAG_OWNER='airflow' AIRFLOW_CTX_DAG_ID='model_training_v1' AIRFLOW_CTX_TASK_ID='get_data' AIRFLOW_CTX_EXECUTION_DATE='2024-06-26T00:00:00+00:00' AIRFLOW_CTX_TRY_NUMBER='1' AIRFLOW_CTX_DAG_RUN_ID='scheduled__2024-06-26T00:00:00+00:00'
[2024-06-27T23:53:10.364+0000] {taskinstance.py:430} INFO - ::endgroup::
[2024-06-27T23:53:10.379+0000] {base.py:84} INFO - Using connection ID 'postgres' for task execution.
[2024-06-27T23:53:10.434+0000] {warnings.py:110} WARNING - /home/airflow/.local/lib/python3.12/site-packages/airflow/providers/common/sql/hooks/sql.py:243: UserWarning: pandas only supports SQLAlchemy connectable (engine/connection) or database string URI or sqlite3 DBAPI2 connection. Other DBAPI2 objects are not tested. Please consider using SQLAlchemy.
  return psql.read_sql(sql, con=conn, params=parameters, **kwargs)

[2024-06-27T23:53:10.439+0000] {taskinstance.py:441} INFO - ::group::Post task execution logs
[2024-06-27T23:53:10.440+0000] {taskinstance.py:2905} ERROR - Task failed with exception
Traceback (most recent call last):
  File "/home/airflow/.local/lib/python3.12/site-packages/pandas/io/sql.py", line 2262, in execute
    cur.execute(sql, *args)
psycopg2.errors.UndefinedTable: ОШИБКА:  отношение "my_table" не существует
LINE 1: SELECT * FROM my_table
                      ^


The above exception was the direct cause of the following exception:

Traceback (most recent call last):
  File "/home/airflow/.local/lib/python3.12/site-packages/airflow/models/taskinstance.py", line 465, in _execute_task
    result = _execute_callable(context=context, **execute_callable_kwargs)
             ^^^^^^^^^^^^^^^^^^^^^^^^^^^^^^^^^^^^^^^^^^^^^^^^^^^^^^^^^^^^^
  File "/home/airflow/.local/lib/python3.12/site-packages/airflow/models/taskinstance.py", line 432, in _execute_callable
    return execute_callable(context=context, **execute_callable_kwargs)
           ^^^^^^^^^^^^^^^^^^^^^^^^^^^^^^^^^^^^^^^^^^^^^^^^^^^^^^^^^^^^
  File "/home/airflow/.local/lib/python3.12/site-packages/airflow/models/baseoperator.py", line 400, in wrapper
    return func(self, *args, **kwargs)
           ^^^^^^^^^^^^^^^^^^^^^^^^^^^
  File "/home/airflow/.local/lib/python3.12/site-packages/airflow/operators/python.py", line 235, in execute
    return_value = self.execute_callable()
                   ^^^^^^^^^^^^^^^^^^^^^^^
  File "/home/airflow/.local/lib/python3.12/site-packages/airflow/operators/python.py", line 252, in execute_callable
    return self.python_callable(*self.op_args, **self.op_kwargs)
           ^^^^^^^^^^^^^^^^^^^^^^^^^^^^^^^^^^^^^^^^^^^^^^^^^^^^^
  File "/opt/airflow/dags/model_training.py", line 31, in get_data
    data = hook.get_pandas_df('SELECT * FROM my_table')
           ^^^^^^^^^^^^^^^^^^^^^^^^^^^^^^^^^^^^^^^^^^^^
  File "/home/airflow/.local/lib/python3.12/site-packages/airflow/providers/common/sql/hooks/sql.py", line 243, in get_pandas_df
    return psql.read_sql(sql, con=conn, params=parameters, **kwargs)
           ^^^^^^^^^^^^^^^^^^^^^^^^^^^^^^^^^^^^^^^^^^^^^^^^^^^^^^^^^
  File "/home/airflow/.local/lib/python3.12/site-packages/pandas/io/sql.py", line 654, in read_sql
    return pandas_sql.read_query(
           ^^^^^^^^^^^^^^^^^^^^^^
  File "/home/airflow/.local/lib/python3.12/site-packages/pandas/io/sql.py", line 2326, in read_query
    cursor = self.execute(sql, params)
             ^^^^^^^^^^^^^^^^^^^^^^^^^
  File "/home/airflow/.local/lib/python3.12/site-packages/pandas/io/sql.py", line 2274, in execute
    raise ex from exc
pandas.errors.DatabaseError: Execution failed on sql 'SELECT * FROM my_table': ОШИБКА:  отношение "my_table" не существует
LINE 1: SELECT * FROM my_table
                      ^

[2024-06-27T23:53:10.448+0000] {taskinstance.py:1206} INFO - Marking task as UP_FOR_RETRY. dag_id=model_training_v1, task_id=get_data, run_id=scheduled__2024-06-26T00:00:00+00:00, execution_date=20240626T000000, start_date=20240627T235310, end_date=20240627T235310
[2024-06-27T23:53:10.457+0000] {standard_task_runner.py:110} ERROR - Failed to execute job 297 for task get_data (Execution failed on sql 'SELECT * FROM my_table': ОШИБКА:  отношение "my_table" не существует
LINE 1: SELECT * FROM my_table
                      ^
; 1793)
[2024-06-27T23:53:10.496+0000] {local_task_job_runner.py:240} INFO - Task exited with return code 1
[2024-06-27T23:53:10.509+0000] {taskinstance.py:3498} INFO - 0 downstream tasks scheduled from follow-on schedule check
[2024-06-27T23:53:10.514+0000] {local_task_job_runner.py:222} INFO - ::endgroup::
