[2024-07-06T23:31:14.021+0000] {local_task_job_runner.py:120} INFO - ::group::Pre task execution logs
[2024-07-06T23:31:14.032+0000] {taskinstance.py:2076} INFO - Dependencies all met for dep_context=non-requeueable deps ti=<TaskInstance: model_training_v56.create_experiment scheduled__2024-07-05T00:00:00+00:00 [queued]>
[2024-07-06T23:31:14.036+0000] {taskinstance.py:2076} INFO - Dependencies all met for dep_context=requeueable deps ti=<TaskInstance: model_training_v56.create_experiment scheduled__2024-07-05T00:00:00+00:00 [queued]>
[2024-07-06T23:31:14.037+0000] {taskinstance.py:2306} INFO - Starting attempt 1 of 2
[2024-07-06T23:31:14.045+0000] {taskinstance.py:2330} INFO - Executing <Task(BashOperator): create_experiment> on 2024-07-05 00:00:00+00:00
[2024-07-06T23:31:14.051+0000] {warnings.py:110} WARNING - /home/airflow/.local/lib/python3.12/site-packages/airflow/task/task_runner/standard_task_runner.py:61: DeprecationWarning: This process (pid=3071) is multi-threaded, use of fork() may lead to deadlocks in the child.
  pid = os.fork()

[2024-07-06T23:31:14.051+0000] {standard_task_runner.py:63} INFO - Started process 3092 to run task
[2024-07-06T23:31:14.051+0000] {standard_task_runner.py:90} INFO - Running: ['airflow', 'tasks', 'run', 'model_training_v56', 'create_experiment', 'scheduled__2024-07-05T00:00:00+00:00', '--job-id', '92', '--raw', '--subdir', 'DAGS_FOLDER/model_training.py', '--cfg-path', '/tmp/tmpx92c5fz3']
[2024-07-06T23:31:14.053+0000] {standard_task_runner.py:91} INFO - Job 92: Subtask create_experiment
[2024-07-06T23:31:14.082+0000] {task_command.py:426} INFO - Running <TaskInstance: model_training_v56.create_experiment scheduled__2024-07-05T00:00:00+00:00 [running]> on host 0823a9cd3c5a
[2024-07-06T23:31:14.134+0000] {taskinstance.py:2648} INFO - Exporting env vars: AIRFLOW_CTX_DAG_OWNER='airflow' AIRFLOW_CTX_DAG_ID='model_training_v56' AIRFLOW_CTX_TASK_ID='create_experiment' AIRFLOW_CTX_EXECUTION_DATE='2024-07-05T00:00:00+00:00' AIRFLOW_CTX_TRY_NUMBER='1' AIRFLOW_CTX_DAG_RUN_ID='scheduled__2024-07-05T00:00:00+00:00'
[2024-07-06T23:31:14.135+0000] {taskinstance.py:430} INFO - ::endgroup::
[2024-07-06T23:31:14.143+0000] {subprocess.py:63} INFO - Tmp dir root location: /tmp
[2024-07-06T23:31:14.144+0000] {subprocess.py:75} INFO - Running command: ['/usr/bin/bash', '-c', 'python dags/tasks/create_experiment.py']
[2024-07-06T23:31:14.152+0000] {subprocess.py:86} INFO - Output:
[2024-07-06T23:31:14.191+0000] {subprocess.py:93} INFO - python: can't open file '/tmp/airflowtmpe4hyu_cb/dags/tasks/create_experiment.py': [Errno 2] No such file or directory
[2024-07-06T23:31:14.193+0000] {subprocess.py:97} INFO - Command exited with return code 2
[2024-07-06T23:31:14.194+0000] {taskinstance.py:441} INFO - ::group::Post task execution logs
[2024-07-06T23:31:14.200+0000] {taskinstance.py:2905} ERROR - Task failed with exception
Traceback (most recent call last):
  File "/home/airflow/.local/lib/python3.12/site-packages/airflow/models/taskinstance.py", line 465, in _execute_task
    result = _execute_callable(context=context, **execute_callable_kwargs)
             ^^^^^^^^^^^^^^^^^^^^^^^^^^^^^^^^^^^^^^^^^^^^^^^^^^^^^^^^^^^^^
  File "/home/airflow/.local/lib/python3.12/site-packages/airflow/models/taskinstance.py", line 432, in _execute_callable
    return execute_callable(context=context, **execute_callable_kwargs)
           ^^^^^^^^^^^^^^^^^^^^^^^^^^^^^^^^^^^^^^^^^^^^^^^^^^^^^^^^^^^^
  File "/home/airflow/.local/lib/python3.12/site-packages/airflow/models/baseoperator.py", line 400, in wrapper
    return func(self, *args, **kwargs)
           ^^^^^^^^^^^^^^^^^^^^^^^^^^^
  File "/home/airflow/.local/lib/python3.12/site-packages/airflow/operators/bash.py", line 243, in execute
    raise AirflowException(
airflow.exceptions.AirflowException: Bash command failed. The command returned a non-zero exit code 2.
[2024-07-06T23:31:14.203+0000] {taskinstance.py:1206} INFO - Marking task as UP_FOR_RETRY. dag_id=model_training_v56, task_id=create_experiment, run_id=scheduled__2024-07-05T00:00:00+00:00, execution_date=20240705T000000, start_date=20240706T233114, end_date=20240706T233114
[2024-07-06T23:31:14.212+0000] {standard_task_runner.py:110} ERROR - Failed to execute job 92 for task create_experiment (Bash command failed. The command returned a non-zero exit code 2.; 3092)
[2024-07-06T23:31:14.225+0000] {local_task_job_runner.py:240} INFO - Task exited with return code 1
[2024-07-06T23:31:14.235+0000] {taskinstance.py:3498} INFO - 0 downstream tasks scheduled from follow-on schedule check
[2024-07-06T23:31:14.238+0000] {local_task_job_runner.py:222} INFO - ::endgroup::
