[2024-06-26T00:09:29.281+0000] {task_context_logger.py:104} ERROR - Executor reports task instance <TaskInstance: create_movie_dataset_v2.get_movies scheduled__2024-06-25T12:00:00+00:00 [queued]> finished (failed) although the task says it's queued. (Info: None) Was the task killed externally?
