[2024-07-06T00:07:31.058+0000] {local_task_job_runner.py:120} INFO - ::group::Pre task execution logs
[2024-07-06T00:07:31.072+0000] {taskinstance.py:2076} INFO - Dependencies all met for dep_context=non-requeueable deps ti=<TaskInstance: model_training_v20.create_bucket scheduled__2024-07-05T00:00:00+00:00 [queued]>
[2024-07-06T00:07:31.076+0000] {taskinstance.py:2076} INFO - Dependencies all met for dep_context=requeueable deps ti=<TaskInstance: model_training_v20.create_bucket scheduled__2024-07-05T00:00:00+00:00 [queued]>
[2024-07-06T00:07:31.077+0000] {taskinstance.py:2306} INFO - Starting attempt 1 of 2
[2024-07-06T00:07:31.086+0000] {taskinstance.py:2330} INFO - Executing <Task(PythonOperator): create_bucket> on 2024-07-05 00:00:00+00:00
[2024-07-06T00:07:31.092+0000] {warnings.py:110} WARNING - /home/airflow/.local/lib/python3.12/site-packages/airflow/task/task_runner/standard_task_runner.py:61: DeprecationWarning: This process (pid=3208) is multi-threaded, use of fork() may lead to deadlocks in the child.
  pid = os.fork()

[2024-07-06T00:07:31.092+0000] {standard_task_runner.py:63} INFO - Started process 3229 to run task
[2024-07-06T00:07:31.092+0000] {standard_task_runner.py:90} INFO - Running: ['airflow', 'tasks', 'run', 'model_training_v20', 'create_bucket', 'scheduled__2024-07-05T00:00:00+00:00', '--job-id', '7', '--raw', '--subdir', 'DAGS_FOLDER/model_training.py', '--cfg-path', '/tmp/tmp_b50h6or']
[2024-07-06T00:07:31.094+0000] {standard_task_runner.py:91} INFO - Job 7: Subtask create_bucket
[2024-07-06T00:07:31.126+0000] {task_command.py:426} INFO - Running <TaskInstance: model_training_v20.create_bucket scheduled__2024-07-05T00:00:00+00:00 [running]> on host a86c24b38e22
[2024-07-06T00:07:31.181+0000] {taskinstance.py:2648} INFO - Exporting env vars: AIRFLOW_CTX_DAG_OWNER='airflow' AIRFLOW_CTX_DAG_ID='model_training_v20' AIRFLOW_CTX_TASK_ID='create_bucket' AIRFLOW_CTX_EXECUTION_DATE='2024-07-05T00:00:00+00:00' AIRFLOW_CTX_TRY_NUMBER='1' AIRFLOW_CTX_DAG_RUN_ID='scheduled__2024-07-05T00:00:00+00:00'
[2024-07-06T00:07:31.182+0000] {taskinstance.py:430} INFO - ::endgroup::
[2024-07-06T00:07:31.203+0000] {taskinstance.py:441} INFO - ::group::Post task execution logs
[2024-07-06T00:07:31.203+0000] {taskinstance.py:2905} ERROR - Task failed with exception
Traceback (most recent call last):
  File "/home/airflow/.local/lib/python3.12/site-packages/airflow/models/taskinstance.py", line 465, in _execute_task
    result = _execute_callable(context=context, **execute_callable_kwargs)
             ^^^^^^^^^^^^^^^^^^^^^^^^^^^^^^^^^^^^^^^^^^^^^^^^^^^^^^^^^^^^^
  File "/home/airflow/.local/lib/python3.12/site-packages/airflow/models/taskinstance.py", line 432, in _execute_callable
    return execute_callable(context=context, **execute_callable_kwargs)
           ^^^^^^^^^^^^^^^^^^^^^^^^^^^^^^^^^^^^^^^^^^^^^^^^^^^^^^^^^^^^
  File "/home/airflow/.local/lib/python3.12/site-packages/airflow/models/baseoperator.py", line 400, in wrapper
    return func(self, *args, **kwargs)
           ^^^^^^^^^^^^^^^^^^^^^^^^^^^
  File "/home/airflow/.local/lib/python3.12/site-packages/airflow/operators/python.py", line 235, in execute
    return_value = self.execute_callable()
                   ^^^^^^^^^^^^^^^^^^^^^^^
  File "/home/airflow/.local/lib/python3.12/site-packages/airflow/operators/python.py", line 252, in execute_callable
    return self.python_callable(*self.op_args, **self.op_kwargs)
           ^^^^^^^^^^^^^^^^^^^^^^^^^^^^^^^^^^^^^^^^^^^^^^^^^^^^^
  File "/opt/airflow/dags/tasks/create_bucket.py", line 5, in create_bucket
    client = Minio(
             ^^^^^^
  File "/home/airflow/.local/lib/python3.12/site-packages/minio/api.py", line 152, in __init__
    self._base_url = BaseURL(
                     ^^^^^^^^
  File "/home/airflow/.local/lib/python3.12/site-packages/minio/helpers.py", line 541, in __init__
    url = _parse_url(endpoint)
          ^^^^^^^^^^^^^^^^^^^^
  File "/home/airflow/.local/lib/python3.12/site-packages/minio/helpers.py", line 502, in _parse_url
    raise ValueError("path in endpoint is not allowed")
ValueError: path in endpoint is not allowed
[2024-07-06T00:07:31.214+0000] {taskinstance.py:1206} INFO - Marking task as UP_FOR_RETRY. dag_id=model_training_v20, task_id=create_bucket, run_id=scheduled__2024-07-05T00:00:00+00:00, execution_date=20240705T000000, start_date=20240706T000731, end_date=20240706T000731
[2024-07-06T00:07:31.225+0000] {standard_task_runner.py:110} ERROR - Failed to execute job 7 for task create_bucket (path in endpoint is not allowed; 3229)
[2024-07-06T00:07:31.265+0000] {local_task_job_runner.py:240} INFO - Task exited with return code 1
[2024-07-06T00:07:31.276+0000] {taskinstance.py:3498} INFO - 0 downstream tasks scheduled from follow-on schedule check
[2024-07-06T00:07:31.279+0000] {local_task_job_runner.py:222} INFO - ::endgroup::
